Workbook

Sheet Jan 2021
B2: Non-Profit Organization Income & Expenses Report
B3: Income & Expense Jauary 2021
E4: Actual | F4: Budget | G4: Difference
B5: Income | E5: =SUM(E7:E8) -> 6.55 | F5: =SUM(F7:F8) -> 0 | G5: =E5-F5 -> 6.55
B6: Savings Account | E6: =E8 -> 6.55 | F6: =SUM(F7:F8) -> 0 | G6: =E6-F6 -> 6.55
C7: Building Fund Contribution | E7: 0 | F7: 0 | G7: =E7-F7 -> 0
C8: Bank Interest | E8: 6.55 | F8: 0 | G8: =E8-F8 -> 6.55
B9: Checking Account | E9: =SUM(E10:E21) -> 3706.46 | F9: =SUM(F10:F21) -> 7705.6533 | G9: =E9-F9 -> -3999.1933
C10: Benevolence Giving In | F10: 0 | G10: =E10-F10 -> 0
C11: MWBC Cooperative Giving | F11: 0 | G11: =E11-F11 -> 0
C12: Lakeland Cooperative Giving | F12: 0 | G12: =E12-F12 -> 0
C13: HBNA Cooperative Giving | F13: 0 | G13: =E13-F13 -> 0
C14: Plate Offering | E14: 1686 | F14: =92467.84/12 -> 7705.6533 | G14: =E14-F14 -> -6019.6533
C15: E-Tithing | E15: 2018.14 | F15: 0 | G15: =E15-F15 -> 2018.14
C16: Fundraise | F16: 0 | G16: =E16-F16 -> 0
C17: Annie Armstrong/Lottie Moon | F17: 0 | G17: =E17-F17 -> 0
C18: Church Rental | F18: 0 | G18: =E18-F18 -> 0
C19: Children's Ministry | F19: 0 | G19: =E19-F19 -> 0
C20: Youth Funds (Donated by church members) | F20: 0 | G20: =E20-F20 -> 0
C21: Others (interest) | E21: 2.32 | F21: 0 | G21: =E21-F21 -> 2.32
B22: Expenses | E22: =SUM(E23:E49) -> 7230.18 | F22: =SUM(F23:F49) -> 7913.9867 | G22: =F22-E22 -> 683.80667
C23: 3000 | D23: Church Mortgage | E23: 787.32 | F23: =9447.84/12 -> 787.32 | G23: =F23-E23 -> 0
C24: 2350 | D24: Insurance, Tax & Fees | E24: 415.32 | F24: =5020/12 -> 418.33333 | G24: =F24-E24 -> 3.0133333
C25: 2320 | D25: Building Property & Ground Maint Upkeep | F25: =14300/12 -> 1191.6667 | G25: =F25-E25 -> 1191.6667
C26: 2330 | D26: Church Equipment Upgrade/Maint/Repair | E26: 290.7 | F26: =3600/12 -> 300 | G26: =F26-E26 -> 9.3
C27: 2340 | D27: Utilities (Spect/Gas/Electric/Water/Sewage) | E27: 1229.09 | F27: =13100/12 -> 1091.6667 | G27: =F27-E27 -> -137.42333
C28: 2310 | D28: Office Administration | E28: 7.75 | F28: =1000/12 -> 83.333333 | G28: =F28-E28 -> 75.583333
C29: 1100 | D29: Cooperative Programs | F29: =1000/12 -> 83.333333 | G29: =F29-E29 -> 83.333333
B30: 1113+1122+1123 | D30: Annie Armstrong, Love&Care & Lottie Moon | F30: 0 | G30: =F30-E30 -> 0
C31: 2180 | D31: Guest Speaker Honor | G31: =F31-E31 -> 0
C32: 2100 | D32: Church Ministries | G32: =F32-E32 -> 0
C33: 2120 | D33: Sunday School Ministry/Nursery | F33: =2300/12 -> 191.66667 | G33: =F33-E33 -> 191.66667
C34: 2135 | D34: Deacons Ministry | F34: =1000/12 -> 83.333333 | G34: =F34-E34 -> 83.333333
C35: 2131 | D35: Womens Ministry | F35: =2000/12 -> 166.66667 | G35: =F35-E35 -> 166.66667
C36: 2132 | D36: Mens Ministry | F36: =500/12 -> 41.666667 | G36: =F36-E36 -> 41.666667
C37: 2133 | D37: Youth Ministry | F37: =500/12 -> 41.666667 | G37: =F37-E37 -> 41.666667
C38: 2040 | D38: General Training | F38: =2000/12 -> 166.66667
C39: 2150 | D39: Evangelism/Outreach Ministry/Web ministry | F39: =2500/12 -> 208.33333 | G39: =F39-E39 -> 208.33333
C40: 2170 | D40: Worship Service Ministry | F40: =2000/12 -> 166.66667 | G40: =F40-E40 -> 166.66667
C41: 2110 | D41: Church Events - CETR | F41: =1200/12 -> 100 | G41: =F41-E41 -> 100
...

Sheet Feb 2021
B2: Non-Profit Organization Income & Expenses Report
B3: Income & Expense February 2021
E4: Actual | F4: Budget | G4: Difference
B5: Income | E5: =SUM(E7:E8) -> 5.91 | F5: =SUM(F7:F8) -> 0 | G5: =E5-F5 -> 5.91
B6: Savings Account | E6: =E8 -> 5.91 | F6: =SUM(F7:F8) -> 0 | G6: =E6-F6 -> 5.91
C7: Building Fund Contribution | E7: 0 | F7: 0 | G7: =E7-F7 -> 0
C8: Bank Interest | E8: 5.91 | F8: 0 | G8: =E8-F8 -> 5.91
B9: Checking Account | E9: =SUM(E10:E21) -> 4052.62 | F9: =SUM(F10:F21) -> 7705.6533 | G9: =E9-F9 -> -3653.0333
C10: Benevolence Giving In | E10: 0 | F10: 0 | G10: =E10-F10 -> 0
C11: MWBC Cooperative Giving | E11: 0 | F11: 0 | G11: =E11-F11 -> 0
C12: Lakeland Cooperative Giving | E12: 0 | F12: 0 | G12: =E12-F12 -> 0
C13: HBNA Cooperative Giving | E13: 0 | F13: 0 | G13: =E13-F13 -> 0
C14: Plate Offering | E14: 2180 | F14: =92467.84/12 -> 7705.6533 | G14: =E14-F14 -> -5525.6533
C15: E-Tithing | E15: 1870.77 | F15: 0 | G15: =E15-F15 -> 1870.77
C16: Fundraise | E16: 0 | F16: 0 | G16: =E16-F16 -> 0
C17: Annie Armstrong/Lottie Moon | F17: 0 | G17: =E17-F17 -> 0
C18: Church Rental | F18: 0 | G18: =E18-F18 -> 0
C19: Children's Ministry | F19: 0 | G19: =E19-F19 -> 0
C20: Youth Funds (Donated by church members) | F20: 0 | G20: =E20-F20 -> 0
C21: Others (interest) | E21: 1.85 | F21: 0 | G21: =E21-F21 -> 1.85
B22: Expenses | E22: =SUM(E23:E49) -> 5079.32 | F22: =SUM(F23:F49) -> 7913.9867 | G22: =F22-E22 -> 2834.6667
C23: 3000 | D23: Church Mortgage | E23: 787.32 | F23: =9447.84/12 -> 787.32 | G23: =F23-E23 -> 0
C24: 2350 | D24: Insurance, Tax & Fees | E24: =56.8 -> 56.8 | F24: =5020/12 -> 418.33333 | G24: =F24-E24 -> 361.53333
C25: 2320 | D25: Building Property & Ground Maint Upkeep | E25: =290.7+1000 -> 1290.7 | F25: =14300/12 -> 1191.6667 | G25: =F25-E25 -> -99.033333
C26: 2330 | D26: Church Equipment Upgrade/Maint/Repair | F26: =3600/12 -> 300 | G26: =F26-E26 -> 300
C27: 2340 | D27: Utilities (Spect/Gas/Electric/Water/Sewage) | E27: 694.5 | F27: =13100/12 -> 1091.6667 | G27: =F27-E27 -> 397.16667
C28: 2310 | D28: Office Administration | F28: =1000/12 -> 83.333333 | G28: =F28-E28 -> 83.333333
C29: 1100 | D29: Cooperative Programs | F29: =1000/12 -> 83.333333 | G29: =F29-E29 -> 83.333333
B30: 1113+1122+1123 | D30: Annie Armstrong, Love&Care & Lottie Moon | F30: 0 | G30: =F30-E30 -> 0
C31: 2180 | D31: Guest Speaker Honor | G31: =F31-E31 -> 0
C32: 2100 | D32: Church Ministries | G32: =F32-E32 -> 0
C33: 2120 | D33: Sunday School Ministry/Nursery | F33: =2300/12 -> 191.66667 | G33: =F33-E33 -> 191.66667
C34: 2135 | D34: Deacons Ministry | F34: =1000/12 -> 83.333333 | G34: =F34-E34 -> 83.333333
C35: 2131 | D35: Womens Ministry | F35: =2000/12 -> 166.66667 | G35: =F35-E35 -> 166.66667
C36: 2132 | D36: Mens Ministry | F36: =500/12 -> 41.666667 | G36: =F36-E36 -> 41.666667
C37: 2133 | D37: Youth Ministry | F37: =500/12 -> 41.666667 | G37: =F37-E37 -> 41.666667
C38: 2040 | D38: General Training | F38: =2000/12 -> 166.66667
C39: 2150 | D39: Evangelism/Outreach Ministry/Web ministry | F39: =2500/12 -> 208.33333 | G39: =F39-E39 -> 208.33333
C40: 2170 | D40: Worship Service Ministry | F40: =2000/12 -> 166.66667 | G40: =F40-E40 -> 166.66667
C41: 2110 | D41: Church Events - CETR | F41: =1200/12 -> 100 | G41: =F41-E41 -> 100
...

Sheet March 2021
B2: Non-Profit Organization Income & Expenses Report
B3: Income & Expense February 2021
E4: Actual | F4: Budget | G4: Difference
B5: Income | E5: =SUM(E7:E8) -> 0 | F5: =SUM(F7:F8) -> 0 | G5: =E5-F5 -> 0
B6: Savings Account | E6: =E8 -> 0 | F6: =SUM(F7:F8) -> 0 | G6: =E6-F6 -> 0
C7: Building Fund Contribution | E7: 0 | F7: 0 | G7: =E7-F7 -> 0
C8: Bank Interest | F8: 0 | G8: =E8-F8 -> 0
B9: Checking Account | E9: =SUM(E10:E21) -> 0 | F9: =SUM(F10:F21) -> 7705.6533 | G9: =E9-F9 -> -7705.6533
C10: Benevolence Giving In | F10: 0 | G10: =E10-F10 -> 0
C11: MWBC Cooperative Giving | F11: 0 | G11: =E11-F11 -> 0
C12: Lakeland Cooperative Giving | F12: 0 | G12: =E12-F12 -> 0
C13: HBNA Cooperative Giving | F13: 0 | G13: =E13-F13 -> 0
C14: Plate Offering | F14: =92467.84/12 -> 7705.6533 | G14: =E14-F14 -> -7705.6533
C15: E-Tithing | F15: 0 | G15: =E15-F15 -> 0
C16: Fundraise | F16: 0 | G16: =E16-F16 -> 0
C17: Annie Armstrong/Lottie Moon | F17: 0 | G17: =E17-F17 -> 0
C18: Church Rental | F18: 0 | G18: =E18-F18 -> 0
C19: Children's Ministry | F19: 0 | G19: =E19-F19 -> 0
C20: Youth Funds (Donated by church members) | F20: 0 | G20: =E20-F20 -> 0
C21: Others (interest) | F21: 0 | G21: =E21-F21 -> 0
B22: Expenses | E22: =SUM(E23:E49) -> 0 | F22: =SUM(F23:F49) -> 7913.9867 | G22: =F22-E22 -> 7913.9867
C23: 3000 | D23: Church Mortgage | F23: =9447.84/12 -> 787.32 | G23: =F23-E23 -> 787.32
C24: 2350 | D24: Insurance, Tax & Fees | F24: =5020/12 -> 418.33333 | G24: =F24-E24 -> 418.33333
C25: 2320 | D25: Building Property & Ground Maint Upkeep | F25: =14300/12 -> 1191.6667 | G25: =F25-E25 -> 1191.6667
C26: 2330 | D26: Church Equipment Upgrade/Maint/Repair | F26: =3600/12 -> 300 | G26: =F26-E26 -> 300
C27: 2340 | D27: Utilities (Spect/Gas/Electric/Water/Sewage) | F27: =13100/12 -> 1091.6667 | G27: =F27-E27 -> 1091.6667
C28: 2310 | D28: Office Administration | F28: =1000/12 -> 83.333333 | G28: =F28-E28 -> 83.333333
C29: 1100 | D29: Cooperative Programs | F29: =1000/12 -> 83.333333 | G29: =F29-E29 -> 83.333333
B30: 1113+1122+1123 | D30: Annie Armstrong, Love&Care & Lottie Moon | F30: 0 | G30: =F30-E30 -> 0
C31: 2180 | D31: Guest Speaker Honor | G31: =F31-E31 -> 0
C32: 2100 | D32: Church Ministries | G32: =F32-E32 -> 0
C33: 2120 | D33: Sunday School Ministry/Nursery | F33: =2300/12 -> 191.66667 | G33: =F33-E33 -> 191.66667
C34: 2135 | D34: Deacons Ministry | F34: =1000/12 -> 83.333333 | G34: =F34-E34 -> 83.333333
C35: 2131 | D35: Womens Ministry | F35: =2000/12 -> 166.66667 | G35: =F35-E35 -> 166.66667
C36: 2132 | D36: Mens Ministry | F36: =500/12 -> 41.666667 | G36: =F36-E36 -> 41.666667
C37: 2133 | D37: Youth Ministry | F37: =500/12 -> 41.666667 | G37: =F37-E37 -> 41.666667
C38: 2040 | D38: General Training | F38: =2000/12 -> 166.66667
C39: 2150 | D39: Evangelism/Outreach Ministry/Web ministry | F39: =2500/12 -> 208.33333 | G39: =F39-E39 -> 208.33333
C40: 2170 | D40: Worship Service Ministry | F40: =2000/12 -> 166.66667 | G40: =F40-E40 -> 166.66667
C41: 2110 | D41: Church Events - CETR | F41: =1200/12 -> 100 | G41: =F41-E41 -> 100
...

Sheet April 2021
B2: Non-Profit Organization Income & Expenses Report
B3: Income & Expense February 2021
E4: Actual | F4: Budget | G4: Difference
B5: Income | E5: =SUM(E7:E8) -> 0 | F5: =SUM(F7:F8) -> 0 | G5: =E5-F5 -> 0
B6: Savings Account | E6: =E8 -> 0 | F6: =SUM(F7:F8) -> 0 | G6: =E6-F6 -> 0
C7: Building Fund Contribution | E7: 0 | F7: 0 | G7: =E7-F7 -> 0
C8: Bank Interest | F8: 0 | G8: =E8-F8 -> 0
B9: Checking Account | E9: =SUM(E10:E21) -> 1.85 | F9: =SUM(F10:F21) -> 7705.6533 | G9: =E9-F9 -> -7703.8033
C10: Benevolence Giving In | F10: 0 | G10: =E10-F10 -> 0
C11: MWBC Cooperative Giving | F11: 0 | G11: =E11-F11 -> 0
C12: Lakeland Cooperative Giving | F12: 0 | G12: =E12-F12 -> 0
C13: HBNA Cooperative Giving | F13: 0 | G13: =E13-F13 -> 0
C14: Plate Offering | F14: =92467.84/12 -> 7705.6533 | G14: =E14-F14 -> -7705.6533
C15: E-Tithing | F15: 0 | G15: =E15-F15 -> 0
C16: Fundraise | F16: 0 | G16: =E16-F16 -> 0
C17: Annie Armstrong/Lottie Moon | F17: 0 | G17: =E17-F17 -> 0
C18: Church Rental | F18: 0 | G18: =E18-F18 -> 0
C19: Children's Ministry | F19: 0 | G19: =E19-F19 -> 0
C20: Youth Funds (Donated by church members) | F20: 0 | G20: =E20-F20 -> 0
C21: Others (interest) | E21: 1.85 | F21: 0 | G21: =E21-F21 -> 1.85
B22: Expenses | E22: =SUM(E23:E49) -> 0 | F22: =SUM(F23:F49) -> 7913.9867 | G22: =F22-E22 -> 7913.9867
C23: 3000 | D23: Church Mortgage | F23: =9447.84/12 -> 787.32 | G23: =F23-E23 -> 787.32
C24: 2350 | D24: Insurance, Tax & Fees | F24: =5020/12 -> 418.33333 | G24: =F24-E24 -> 418.33333
C25: 2320 | D25: Building Property & Ground Maint Upkeep | F25: =14300/12 -> 1191.6667 | G25: =F25-E25 -> 1191.6667
C26: 2330 | D26: Church Equipment Upgrade/Maint/Repair | F26: =3600/12 -> 300 | G26: =F26-E26 -> 300
C27: 2340 | D27: Utilities (Spect/Gas/Electric/Water/Sewage) | F27: =13100/12 -> 1091.6667 | G27: =F27-E27 -> 1091.6667
C28: 2310 | D28: Office Administration | F28: =1000/12 -> 83.333333 | G28: =F28-E28 -> 83.333333
C29: 1100 | D29: Cooperative Programs | F29: =1000/12 -> 83.333333 | G29: =F29-E29 -> 83.333333
B30: 1113+1122+1123 | D30: Annie Armstrong, Love&Care & Lottie Moon | F30: 0 | G30: =F30-E30 -> 0
C31: 2180 | D31: Guest Speaker Honor | G31: =F31-E31 -> 0
C32: 2100 | D32: Church Ministries | G32: =F32-E32 -> 0
C33: 2120 | D33: Sunday School Ministry/Nursery | F33: =2300/12 -> 191.66667 | G33: =F33-E33 -> 191.66667
C34: 2135 | D34: Deacons Ministry | F34: =1000/12 -> 83.333333 | G34: =F34-E34 -> 83.333333
C35: 2131 | D35: Womens Ministry | F35: =2000/12 -> 166.66667 | G35: =F35-E35 -> 166.66667
C36: 2132 | D36: Mens Ministry | F36: =500/12 -> 41.666667 | G36: =F36-E36 -> 41.666667
C37: 2133 | D37: Youth Ministry | F37: =500/12 -> 41.666667 | G37: =F37-E37 -> 41.666667
C38: 2040 | D38: General Training | F38: =2000/12 -> 166.66667
C39: 2150 | D39: Evangelism/Outreach Ministry/Web ministry | F39: =2500/12 -> 208.33333 | G39: =F39-E39 -> 208.33333
C40: 2170 | D40: Worship Service Ministry | F40: =2000/12 -> 166.66667 | G40: =F40-E40 -> 166.66667
C41: 2110 | D41: Church Events - CETR | F41: =1200/12 -> 100 | G41: =F41-E41 -> 100
...

Sheet May 2021
B2: Non-Profit Organization Income & Expenses Report
B3: Income & Expense February 2021
E4: Actual | F4: Budget | G4: Difference
B5: Income | E5: =SUM(E7:E8) -> 0 | F5: =SUM(F7:F8) -> 0 | G5: =E5-F5 -> 0
B6: Savings Account | E6: =E8 -> 0 | F6: =SUM(F7:F8) -> 0 | G6: =E6-F6 -> 0
C7: Building Fund Contribution | E7: 0 | F7: 0 | G7: =E7-F7 -> 0
C8: Bank Interest | F8: 0 | G8: =E8-F8 -> 0
B9: Checking Account | E9: =SUM(E10:E21) -> 0 | F9: =SUM(F10:F21) -> 7705.6533 | G9: =E9-F9 -> -7705.6533
C10: Benevolence Giving In | F10: 0 | G10: =E10-F10 -> 0
C11: MWBC Cooperative Giving | F11: 0 | G11: =E11-F11 -> 0
C12: Lakeland Cooperative Giving | F12: 0 | G12: =E12-F12 -> 0
C13: HBNA Cooperative Giving | F13: 0 | G13: =E13-F13 -> 0
C14: Plate Offering | F14: =92467.84/12 -> 7705.6533 | G14: =E14-F14 -> -7705.6533
C15: E-Tithing | F15: 0 | G15: =E15-F15 -> 0
C16: Fundraise | F16: 0 | G16: =E16-F16 -> 0
C17: Annie Armstrong/Lottie Moon | F17: 0 | G17: =E17-F17 -> 0
C18: Church Rental | F18: 0 | G18: =E18-F18 -> 0
C19: Children's Ministry | F19: 0 | G19: =E19-F19 -> 0
C20: Youth Funds (Donated by church members) | F20: 0 | G20: =E20-F20 -> 0
C21: Others (interest) | F21: 0 | G21: =E21-F21 -> 0
B22: Expenses | E22: =SUM(E23:E49) -> 0 | F22: =SUM(F23:F49) -> 7913.9867 | G22: =F22-E22 -> 7913.9867
C23: 3000 | D23: Church Mortgage | F23: =9447.84/12 -> 787.32 | G23: =F23-E23 -> 787.32
C24: 2350 | D24: Insurance, Tax & Fees | F24: =5020/12 -> 418.33333 | G24: =F24-E24 -> 418.33333
C25: 2320 | D25: Building Property & Ground Maint Upkeep | F25: =14300/12 -> 1191.6667 | G25: =F25-E25 -> 1191.6667
C26: 2330 | D26: Church Equipment Upgrade/Maint/Repair | F26: =3600/12 -> 300 | G26: =F26-E26 -> 300
C27: 2340 | D27: Utilities (Spect/Gas/Electric/Water/Sewage) | F27: =13100/12 -> 1091.6667 | G27: =F27-E27 -> 1091.6667
C28: 2310 | D28: Office Administration | F28: =1000/12 -> 83.333333 | G28: =F28-E28 -> 83.333333
C29: 1100 | D29: Cooperative Programs | F29: =1000/12 -> 83.333333 | G29: =F29-E29 -> 83.333333
B30: 1113+1122+1123 | D30: Annie Armstrong, Love&Care & Lottie Moon | F30: 0 | G30: =F30-E30 -> 0
C31: 2180 | D31: Guest Speaker Honor | G31: =F31-E31 -> 0
C32: 2100 | D32: Church Ministries | G32: =F32-E32 -> 0
C33: 2120 | D33: Sunday School Ministry/Nursery | F33: =2300/12 -> 191.66667 | G33: =F33-E33 -> 191.66667
C34: 2135 | D34: Deacons Ministry | F34: =1000/12 -> 83.333333 | G34: =F34-E34 -> 83.333333
C35: 2131 | D35: Womens Ministry | F35: =2000/12 -> 166.66667 | G35: =F35-E35 -> 166.66667
C36: 2132 | D36: Mens Ministry | F36: =500/12 -> 41.666667 | G36: =F36-E36 -> 41.666667
C37: 2133 | D37: Youth Ministry | F37: =500/12 -> 41.666667 | G37: =F37-E37 -> 41.666667
C38: 2040 | D38: General Training | F38: =2000/12 -> 166.66667
C39: 2150 | D39: Evangelism/Outreach Ministry/Web ministry | F39: =2500/12 -> 208.33333 | G39: =F39-E39 -> 208.33333
C40: 2170 | D40: Worship Service Ministry | F40: =2000/12 -> 166.66667 | G40: =F40-E40 -> 166.66667
C41: 2110 | D41: Church Events - CETR | F41: =1200/12 -> 100 | G41: =F41-E41 -> 100
...

Sheet June 2021
B2: Non-Profit Organization Income & Expenses Report
B3: Income & Expense February 2021
E4: Actual | F4: Budget | G4: Difference
B5: Income | E5: =SUM(E7:E8) -> 0 | F5: =SUM(F7:F8) -> 0 | G5: =E5-F5 -> 0
B6: Savings Account | E6: =E8 -> 0 | F6: =SUM(F7:F8) -> 0 | G6: =E6-F6 -> 0
C7: Building Fund Contribution | E7: 0 | F7: 0 | G7: =E7-F7 -> 0
C8: Bank Interest | F8: 0 | G8: =E8-F8 -> 0
B9: Checking Account | E9: =SUM(E10:E21) -> 0 | F9: =SUM(F10:F21) -> 7705.6533 | G9: =E9-F9 -> -7705.6533
C10: Benevolence Giving In | E10: 0 | F10: 0 | G10: =E10-F10 -> 0
C11: MWBC Cooperative Giving | E11: 0 | F11: 0 | G11: =E11-F11 -> 0
C12: Lakeland Cooperative Giving | E12: 0 | F12: 0 | G12: =E12-F12 -> 0
C13: HBNA Cooperative Giving | E13: 0 | F13: 0 | G13: =E13-F13 -> 0
C14: Plate Offering | F14: =92467.84/12 -> 7705.6533 | G14: =E14-F14 -> -7705.6533
C15: E-Tithing | F15: 0 | G15: =E15-F15 -> 0
C16: Fundraise | F16: 0 | G16: =E16-F16 -> 0
C17: Annie Armstrong/Lottie Moon | F17: 0 | G17: =E17-F17 -> 0
C18: Church Rental | F18: 0 | G18: =E18-F18 -> 0
C19: Children's Ministry | F19: 0 | G19: =E19-F19 -> 0
C20: Youth Funds (Donated by church members) | F20: 0 | G20: =E20-F20 -> 0
C21: Others (interest) | F21: 0 | G21: =E21-F21 -> 0
B22: Expenses | E22: =SUM(E23:E49) -> 0 | F22: =SUM(F23:F49) -> 7913.9867 | G22: =F22-E22 -> 7913.9867
C23: 3000 | D23: Church Mortgage | F23: =9447.84/12 -> 787.32 | G23: =F23-E23 -> 787.32
C24: 2350 | D24: Insurance, Tax & Fees | F24: =5020/12 -> 418.33333 | G24: =F24-E24 -> 418.33333
C25: 2320 | D25: Building Property & Ground Maint Upkeep | F25: =14300/12 -> 1191.6667 | G25: =F25-E25 -> 1191.6667
C26: 2330 | D26: Church Equipment Upgrade/Maint/Repair | F26: =3600/12 -> 300 | G26: =F26-E26 -> 300
C27: 2340 | D27: Utilities (Spect/Gas/Electric/Water/Sewage) | F27: =13100/12 -> 1091.6667 | G27: =F27-E27 -> 1091.6667
C28: 2310 | D28: Office Administration | F28: =1000/12 -> 83.333333 | G28: =F28-E28 -> 83.333333
C29: 1100 | D29: Cooperative Programs | F29: =1000/12 -> 83.333333 | G29: =F29-E29 -> 83.333333
B30: 1113+1122+1123 | D30: Annie Armstrong, Love&Care & Lottie Moon | F30: 0 | G30: =F30-E30 -> 0
C31: 2180 | D31: Guest Speaker Honor | G31: =F31-E31 -> 0
C32: 2100 | D32: Church Ministries | G32: =F32-E32 -> 0
C33: 2120 | D33: Sunday School Ministry/Nursery | F33: =2300/12 -> 191.66667 | G33: =F33-E33 -> 191.66667
C34: 2135 | D34: Deacons Ministry | F34: =1000/12 -> 83.333333 | G34: =F34-E34 -> 83.333333
C35: 2131 | D35: Womens Ministry | F35: =2000/12 -> 166.66667 | G35: =F35-E35 -> 166.66667
C36: 2132 | D36: Mens Ministry | F36: =500/12 -> 41.666667 | G36: =F36-E36 -> 41.666667
C37: 2133 | D37: Youth Ministry | F37: =500/12 -> 41.666667 | G37: =F37-E37 -> 41.666667
C38: 2040 | D38: General Training | F38: =2000/12 -> 166.66667
C39: 2150 | D39: Evangelism/Outreach Ministry/Web ministry | F39: =2500/12 -> 208.33333 | G39: =F39-E39 -> 208.33333
C40: 2170 | D40: Worship Service Ministry | F40: =2000/12 -> 166.66667 | G40: =F40-E40 -> 166.66667
C41: 2110 | D41: Church Events - CETR | F41: =1200/12 -> 100 | G41: =F41-E41 -> 100
...

Sheet July 2021
B2: Non-Profit Organization Income & Expenses Report
B3: Income & Expense February 2021
E4: Actual | F4: Budget | G4: Difference
B5: Income | E5: =SUM(E7:E8) -> 0 | F5: =SUM(F7:F8) -> 0 | G5: =E5-F5 -> 0
B6: Savings Account | E6: =E8 -> 0 | F6: =SUM(F7:F8) -> 0 | G6: =E6-F6 -> 0
C7: Building Fund Contribution | E7: 0 | F7: 0 | G7: =E7-F7 -> 0
C8: Bank Interest | F8: 0 | G8: =E8-F8 -> 0
B9: Checking Account | E9: =SUM(E10:E21) -> 0 | F9: =SUM(F10:F21) -> 7705.6533 | G9: =E9-F9 -> -7705.6533
C10: Benevolence Giving In | F10: 0 | G10: =E10-F10 -> 0
C11: MWBC Cooperative Giving | F11: 0 | G11: =E11-F11 -> 0
C12: Lakeland Cooperative Giving | F12: 0 | G12: =E12-F12 -> 0
C13: HBNA Cooperative Giving | F13: 0 | G13: =E13-F13 -> 0
C14: Plate Offering | F14: =92467.84/12 -> 7705.6533 | G14: =E14-F14 -> -7705.6533
C15: E-Tithing | F15: 0 | G15: =E15-F15 -> 0
C16: Fundraise | F16: 0 | G16: =E16-F16 -> 0
C17: Annie Armstrong/Lottie Moon | F17: 0 | G17: =E17-F17 -> 0
C18: Church Rental | F18: 0 | G18: =E18-F18 -> 0
C19: Children's Ministry | F19: 0 | G19: =E19-F19 -> 0
C20: Youth Funds (Donated by church members) | F20: 0 | G20: =E20-F20 -> 0
C21: Others (interest) | F21: 0 | G21: =E21-F21 -> 0
B22: Expenses | E22: =SUM(E23:E49) -> 0 | F22: =SUM(F23:F49) -> 7913.9867 | G22: =F22-E22 -> 7913.9867
C23: 3000 | D23: Church Mortgage | F23: =9447.84/12 -> 787.32 | G23: =F23-E23 -> 787.32
C24: 2350 | D24: Insurance, Tax & Fees | F24: =5020/12 -> 418.33333 | G24: =F24-E24 -> 418.33333
C25: 2320 | D25: Building Property & Ground Maint Upkeep | F25: =14300/12 -> 1191.6667 | G25: =F25-E25 -> 1191.6667
C26: 2330 | D26: Church Equipment Upgrade/Maint/Repair | F26: =3600/12 -> 300 | G26: =F26-E26 -> 300
C27: 2340 | D27: Utilities (Spect/Gas/Electric/Water/Sewage) | F27: =13100/12 -> 1091.6667 | G27: =F27-E27 -> 1091.6667
C28: 2310 | D28: Office Administration | F28: =1000/12 -> 83.333333 | G28: =F28-E28 -> 83.333333
C29: 1100 | D29: Cooperative Programs | F29: =1000/12 -> 83.333333 | G29: =F29-E29 -> 83.333333
B30: 1113+1122+1123 | D30: Annie Armstrong, Love&Care & Lottie Moon | F30: 0 | G30: =F30-E30 -> 0
C31: 2180 | D31: Guest Speaker Honor | G31: =F31-E31 -> 0
C32: 2100 | D32: Church Ministries | G32: =F32-E32 -> 0
C33: 2120 | D33: Sunday School Ministry/Nursery | F33: =2300/12 -> 191.66667 | G33: =F33-E33 -> 191.66667
C34: 2135 | D34: Deacons Ministry | F34: =1000/12 -> 83.333333 | G34: =F34-E34 -> 83.333333
C35: 2131 | D35: Womens Ministry | F35: =2000/12 -> 166.66667 | G35: =F35-E35 -> 166.66667
C36: 2132 | D36: Mens Ministry | F36: =500/12 -> 41.666667 | G36: =F36-E36 -> 41.666667
C37: 2133 | D37: Youth Ministry | F37: =500/12 -> 41.666667 | G37: =F37-E37 -> 41.666667
C38: 2040 | D38: General Training | F38: =2000/12 -> 166.66667
C39: 2150 | D39: Evangelism/Outreach Ministry/Web ministry | F39: =2500/12 -> 208.33333 | G39: =F39-E39 -> 208.33333
C40: 2170 | D40: Worship Service Ministry | F40: =2000/12 -> 166.66667 | G40: =F40-E40 -> 166.66667
C41: 2110 | D41: Church Events - CETR | F41: =1200/12 -> 100 | G41: =F41-E41 -> 100
...

Sheet Aug 2021
B2: Non-Profit Organization Income & Expenses Report
B3: Income & Expense February 2021
E4: Actual | F4: Budget | G4: Difference
B5: Income | E5: =SUM(E7:E8) -> 0 | F5: =SUM(F7:F8) -> 0 | G5: =E5-F5 -> 0
B6: Savings Account | E6: =E8 -> 0 | F6: =SUM(F7:F8) -> 0 | G6: =E6-F6 -> 0
C7: Building Fund Contribution | E7: 0 | F7: 0 | G7: =E7-F7 -> 0
C8: Bank Interest | F8: 0 | G8: =E8-F8 -> 0
B9: Checking Account | E9: =SUM(E10:E21) -> 0 | F9: =SUM(F10:F21) -> 7705.6533 | G9: =E9-F9 -> -7705.6533
C10: Benevolence Giving In | F10: 0 | G10: =E10-F10 -> 0
C11: MWBC Cooperative Giving | F11: 0 | G11: =E11-F11 -> 0
C12: Lakeland Cooperative Giving | F12: 0 | G12: =E12-F12 -> 0
C13: HBNA Cooperative Giving | F13: 0 | G13: =E13-F13 -> 0
C14: Plate Offering | F14: =92467.84/12 -> 7705.6533 | G14: =E14-F14 -> -7705.6533
C15: E-Tithing | F15: 0 | G15: =E15-F15 -> 0
C16: Fundraise | F16: 0 | G16: =E16-F16 -> 0
C17: Annie Armstrong/Lottie Moon | F17: 0 | G17: =E17-F17 -> 0
C18: Church Rental | F18: 0 | G18: =E18-F18 -> 0
C19: Children's Ministry | F19: 0 | G19: =E19-F19 -> 0
C20: Youth Funds (Donated by church members) | F20: 0 | G20: =E20-F20 -> 0
C21: Others (interest) | F21: 0 | G21: =E21-F21 -> 0
B22: Expenses | E22: =SUM(E23:E49) -> 0 | F22: =SUM(F23:F49) -> 7913.9867 | G22: =F22-E22 -> 7913.9867
C23: 3000 | D23: Church Mortgage | F23: =9447.84/12 -> 787.32 | G23: =F23-E23 -> 787.32
C24: 2350 | D24: Insurance, Tax & Fees | F24: =5020/12 -> 418.33333 | G24: =F24-E24 -> 418.33333
C25: 2320 | D25: Building Property & Ground Maint Upkeep | F25: =14300/12 -> 1191.6667 | G25: =F25-E25 -> 1191.6667
C26: 2330 | D26: Church Equipment Upgrade/Maint/Repair | F26: =3600/12 -> 300 | G26: =F26-E26 -> 300
C27: 2340 | D27: Utilities (Spect/Gas/Electric/Water/Sewage) | F27: =13100/12 -> 1091.6667 | G27: =F27-E27 -> 1091.6667
C28: 2310 | D28: Office Administration | F28: =1000/12 -> 83.333333 | G28: =F28-E28 -> 83.333333
C29: 1100 | D29: Cooperative Programs | F29: =1000/12 -> 83.333333 | G29: =F29-E29 -> 83.333333
B30: 1113+1122+1123 | D30: Annie Armstrong, Love&Care & Lottie Moon | F30: 0 | G30: =F30-E30 -> 0
C31: 2180 | D31: Guest Speaker Honor | G31: =F31-E31 -> 0
C32: 2100 | D32: Church Ministries | G32: =F32-E32 -> 0
C33: 2120 | D33: Sunday School Ministry/Nursery | F33: =2300/12 -> 191.66667 | G33: =F33-E33 -> 191.66667
C34: 2135 | D34: Deacons Ministry | F34: =1000/12 -> 83.333333 | G34: =F34-E34 -> 83.333333
C35: 2131 | D35: Womens Ministry | F35: =2000/12 -> 166.66667 | G35: =F35-E35 -> 166.66667
C36: 2132 | D36: Mens Ministry | F36: =500/12 -> 41.666667 | G36: =F36-E36 -> 41.666667
C37: 2133 | D37: Youth Ministry | F37: =500/12 -> 41.666667 | G37: =F37-E37 -> 41.666667
C38: 2040 | D38: General Training | F38: =2000/12 -> 166.66667
C39: 2150 | D39: Evangelism/Outreach Ministry/Web ministry | F39: =2500/12 -> 208.33333 | G39: =F39-E39 -> 208.33333
C40: 2170 | D40: Worship Service Ministry | F40: =2000/12 -> 166.66667 | G40: =F40-E40 -> 166.66667
C41: 2110 | D41: Church Events - CETR | F41: =1200/12 -> 100 | G41: =F41-E41 -> 100
...

Sheet Sept 2021
B2: Non-Profit Organization Income & Expenses Report
B3: Income & Expense February 2021
E4: Actual | F4: Budget | G4: Difference
B5: Income | E5: =SUM(E7:E8) -> 0 | F5: =SUM(F7:F8) -> 0 | G5: =E5-F5 -> 0
B6: Savings Account | E6: =E8 -> 0 | F6: =SUM(F7:F8) -> 0 | G6: =E6-F6 -> 0
C7: Building Fund Contribution | E7: 0 | F7: 0 | G7: =E7-F7 -> 0
C8: Bank Interest | F8: 0 | G8: =E8-F8 -> 0
B9: Checking Account | E9: =SUM(E10:E21) -> 0 | F9: =SUM(F10:F21) -> 7705.6533 | G9: =E9-F9 -> -7705.6533
C10: Benevolence Giving In | F10: 0 | G10: =E10-F10 -> 0
C11: MWBC Cooperative Giving | F11: 0 | G11: =E11-F11 -> 0
C12: Lakeland Cooperative Giving | F12: 0 | G12: =E12-F12 -> 0
C13: HBNA Cooperative Giving | F13: 0 | G13: =E13-F13 -> 0
C14: Plate Offering | F14: =92467.84/12 -> 7705.6533 | G14: =E14-F14 -> -7705.6533
C15: E-Tithing | F15: 0 | G15: =E15-F15 -> 0
C16: Fundraise | F16: 0 | G16: =E16-F16 -> 0
C17: Annie Armstrong/Lottie Moon | F17: 0 | G17: =E17-F17 -> 0
C18: Church Rental | F18: 0 | G18: =E18-F18 -> 0
C19: Children's Ministry | F19: 0 | G19: =E19-F19 -> 0
C20: Youth Funds (Donated by church members) | F20: 0 | G20: =E20-F20 -> 0
C21: Others (interest) | F21: 0 | G21: =E21-F21 -> 0
B22: Expenses | E22: =SUM(E23:E49) -> 0 | F22: =SUM(F23:F49) -> 7913.9867 | G22: =F22-E22 -> 7913.9867
C23: 3000 | D23: Church Mortgage | F23: =9447.84/12 -> 787.32 | G23: =F23-E23 -> 787.32
C24: 2350 | D24: Insurance, Tax & Fees | F24: =5020/12 -> 418.33333 | G24: =F24-E24 -> 418.33333
C25: 2320 | D25: Building Property & Ground Maint Upkeep | F25: =14300/12 -> 1191.6667 | G25: =F25-E25 -> 1191.6667
C26: 2330 | D26: Church Equipment Upgrade/Maint/Repair | F26: =3600/12 -> 300 | G26: =F26-E26 -> 300
C27: 2340 | D27: Utilities (Spect/Gas/Electric/Water/Sewage) | F27: =13100/12 -> 1091.6667 | G27: =F27-E27 -> 1091.6667
C28: 2310 | D28: Office Administration | F28: =1000/12 -> 83.333333 | G28: =F28-E28 -> 83.333333
C29: 1100 | D29: Cooperative Programs | F29: =1000/12 -> 83.333333 | G29: =F29-E29 -> 83.333333
B30: 1113+1122+1123 | D30: Annie Armstrong, Love&Care & Lottie Moon | F30: 0 | G30: =F30-E30 -> 0
C31: 2180 | D31: Guest Speaker Honor | G31: =F31-E31 -> 0
C32: 2100 | D32: Church Ministries | G32: =F32-E32 -> 0
C33: 2120 | D33: Sunday School Ministry/Nursery | F33: =2300/12 -> 191.66667 | G33: =F33-E33 -> 191.66667
C34: 2135 | D34: Deacons Ministry | F34: =1000/12 -> 83.333333 | G34: =F34-E34 -> 83.333333
C35: 2131 | D35: Womens Ministry | F35: =2000/12 -> 166.66667 | G35: =F35-E35 -> 166.66667
C36: 2132 | D36: Mens Ministry | F36: =500/12 -> 41.666667 | G36: =F36-E36 -> 41.666667
C37: 2133 | D37: Youth Ministry | F37: =500/12 -> 41.666667 | G37: =F37-E37 -> 41.666667
C38: 2040 | D38: General Training | F38: =2000/12 -> 166.66667
C39: 2150 | D39: Evangelism/Outreach Ministry/Web ministry | F39: =2500/12 -> 208.33333 | G39: =F39-E39 -> 208.33333
C40: 2170 | D40: Worship Service Ministry | F40: =2000/12 -> 166.66667 | G40: =F40-E40 -> 166.66667
C41: 2110 | D41: Church Events - CETR | F41: =1200/12 -> 100 | G41: =F41-E41 -> 100
...

Sheet Oct 2021
B2: Non-Profit Organization Income & Expenses Report
B3: Income & Expense February 2021
E4: Actual | F4: Budget | G4: Difference
B5: Income | E5: =SUM(E7:E8) -> 0 | F5: =SUM(F7:F8) -> 0 | G5: =E5-F5 -> 0
B6: Savings Account | E6: =E8 -> 0 | F6: =SUM(F7:F8) -> 0 | G6: =E6-F6 -> 0
C7: Building Fund Contribution | E7: 0 | F7: 0 | G7: =E7-F7 -> 0
C8: Bank Interest | F8: 0 | G8: =E8-F8 -> 0
B9: Checking Account | E9: =SUM(E10:E21) -> 0 | F9: =SUM(F10:F21) -> 7705.6533 | G9: =E9-F9 -> -7705.6533
C10: Benevolence Giving In | F10: 0 | G10: =E10-F10 -> 0
C11: MWBC Cooperative Giving | F11: 0 | G11: =E11-F11 -> 0
C12: Lakeland Cooperative Giving | F12: 0 | G12: =E12-F12 -> 0
C13: HBNA Cooperative Giving | F13: 0 | G13: =E13-F13 -> 0
C14: Plate Offering | F14: =92467.84/12 -> 7705.6533 | G14: =E14-F14 -> -7705.6533
C15: E-Tithing | F15: 0 | G15: =E15-F15 -> 0
C16: Fundraise | F16: 0 | G16: =E16-F16 -> 0
C17: Annie Armstrong/Lottie Moon | F17: 0 | G17: =E17-F17 -> 0
C18: Church Rental | F18: 0 | G18: =E18-F18 -> 0
C19: Children's Ministry | F19: 0 | G19: =E19-F19 -> 0
C20: Youth Funds (Donated by church members) | F20: 0 | G20: =E20-F20 -> 0
C21: Others (interest) | F21: 0 | G21: =E21-F21 -> 0
B22: Expenses | E22: =SUM(E23:E49) -> 0 | F22: =SUM(F23:F49) -> 7913.9867 | G22: =F22-E22 -> 7913.9867
C23: 3000 | D23: Church Mortgage | F23: =9447.84/12 -> 787.32 | G23: =F23-E23 -> 787.32
C24: 2350 | D24: Insurance, Tax & Fees | F24: =5020/12 -> 418.33333 | G24: =F24-E24 -> 418.33333
C25: 2320 | D25: Building Property & Ground Maint Upkeep | F25: =14300/12 -> 1191.6667 | G25: =F25-E25 -> 1191.6667
C26: 2330 | D26: Church Equipment Upgrade/Maint/Repair | F26: =3600/12 -> 300 | G26: =F26-E26 -> 300
C27: 2340 | D27: Utilities (Spect/Gas/Electric/Water/Sewage) | F27: =13100/12 -> 1091.6667 | G27: =F27-E27 -> 1091.6667
C28: 2310 | D28: Office Administration | F28: =1000/12 -> 83.333333 | G28: =F28-E28 -> 83.333333
C29: 1100 | D29: Cooperative Programs | F29: =1000/12 -> 83.333333 | G29: =F29-E29 -> 83.333333
B30: 1113+1122+1123 | D30: Annie Armstrong, Love&Care & Lottie Moon | F30: 0 | G30: =F30-E30 -> 0
C31: 2180 | D31: Guest Speaker Honor | G31: =F31-E31 -> 0
C32: 2100 | D32: Church Ministries | G32: =F32-E32 -> 0
C33: 2120 | D33: Sunday School Ministry/Nursery | F33: =2300/12 -> 191.66667 | G33: =F33-E33 -> 191.66667
C34: 2135 | D34: Deacons Ministry | F34: =1000/12 -> 83.333333 | G34: =F34-E34 -> 83.333333
C35: 2131 | D35: Womens Ministry | F35: =2000/12 -> 166.66667 | G35: =F35-E35 -> 166.66667
C36: 2132 | D36: Mens Ministry | F36: =500/12 -> 41.666667 | G36: =F36-E36 -> 41.666667
C37: 2133 | D37: Youth Ministry | F37: =500/12 -> 41.666667 | G37: =F37-E37 -> 41.666667
C38: 2040 | D38: General Training | F38: =2000/12 -> 166.66667
C39: 2150 | D39: Evangelism/Outreach Ministry/Web ministry | F39: =2500/12 -> 208.33333 | G39: =F39-E39 -> 208.33333
C40: 2170 | D40: Worship Service Ministry | F40: =2000/12 -> 166.66667 | G40: =F40-E40 -> 166.66667
C41: 2110 | D41: Church Events - CETR | F41: =1200/12 -> 100 | G41: =F41-E41 -> 100
...

Sheet Nov 2021
B2: Non-Profit Organization Income & Expenses Report
B3: Income & Expense February 2021
E4: Actual | F4: Budget | G4: Difference
B5: Income | E5: =SUM(E7:E8) -> 0 | F5: =SUM(F7:F8) -> 0 | G5: =E5-F5 -> 0
B6: Savings Account | E6: =E8 -> 0 | F6: =SUM(F7:F8) -> 0 | G6: =E6-F6 -> 0
C7: Building Fund Contribution | E7: 0 | F7: 0 | G7: =E7-F7 -> 0
C8: Bank Interest | F8: 0 | G8: =E8-F8 -> 0
B9: Checking Account | E9: =SUM(E10:E21) -> 0 | F9: =SUM(F10:F21) -> 7705.6533 | G9: =E9-F9 -> -7705.6533
C10: Benevolence Giving In | F10: 0 | G10: =E10-F10 -> 0
C11: MWBC Cooperative Giving | F11: 0 | G11: =E11-F11 -> 0
C12: Lakeland Cooperative Giving | F12: 0 | G12: =E12-F12 -> 0
C13: HBNA Cooperative Giving | F13: 0 | G13: =E13-F13 -> 0
C14: Plate Offering | F14: =92467.84/12 -> 7705.6533 | G14: =E14-F14 -> -7705.6533
C15: E-Tithing | F15: 0 | G15: =E15-F15 -> 0
C16: Fundraise | F16: 0 | G16: =E16-F16 -> 0
C17: Annie Armstrong/Lottie Moon | F17: 0 | G17: =E17-F17 -> 0
C18: Church Rental | F18: 0 | G18: =E18-F18 -> 0
C19: Children's Ministry | F19: 0 | G19: =E19-F19 -> 0
C20: Youth Funds (Donated by church members) | F20: 0 | G20: =E20-F20 -> 0
C21: Others (interest) | F21: 0 | G21: =E21-F21 -> 0
B22: Expenses | E22: =SUM(E23:E49) -> 0 | F22: =SUM(F23:F49) -> 7913.9867 | G22: =F22-E22 -> 7913.9867
C23: 3000 | D23: Church Mortgage | F23: =9447.84/12 -> 787.32 | G23: =F23-E23 -> 787.32
C24: 2350 | D24: Insurance, Tax & Fees | F24: =5020/12 -> 418.33333 | G24: =F24-E24 -> 418.33333
C25: 2320 | D25: Building Property & Ground Maint Upkeep | F25: =14300/12 -> 1191.6667 | G25: =F25-E25 -> 1191.6667
C26: 2330 | D26: Church Equipment Upgrade/Maint/Repair | F26: =3600/12 -> 300 | G26: =F26-E26 -> 300
C27: 2340 | D27: Utilities (Spect/Gas/Electric/Water/Sewage) | F27: =13100/12 -> 1091.6667 | G27: =F27-E27 -> 1091.6667
C28: 2310 | D28: Office Administration | F28: =1000/12 -> 83.333333 | G28: =F28-E28 -> 83.333333
C29: 1100 | D29: Cooperative Programs | F29: =1000/12 -> 83.333333 | G29: =F29-E29 -> 83.333333
B30: 1113+1122+1123 | D30: Annie Armstrong, Love&Care & Lottie Moon | F30: 0 | G30: =F30-E30 -> 0
C31: 2180 | D31: Guest Speaker Honor | G31: =F31-E31 -> 0
C32: 2100 | D32: Church Ministries | G32: =F32-E32 -> 0
C33: 2120 | D33: Sunday School Ministry/Nursery | F33: =2300/12 -> 191.66667 | G33: =F33-E33 -> 191.66667
C34: 2135 | D34: Deacons Ministry | F34: =1000/12 -> 83.333333 | G34: =F34-E34 -> 83.333333
C35: 2131 | D35: Womens Ministry | F35: =2000/12 -> 166.66667 | G35: =F35-E35 -> 166.66667
C36: 2132 | D36: Mens Ministry | F36: =500/12 -> 41.666667 | G36: =F36-E36 -> 41.666667
C37: 2133 | D37: Youth Ministry | F37: =500/12 -> 41.666667 | G37: =F37-E37 -> 41.666667
C38: 2040 | D38: General Training | F38: =2000/12 -> 166.66667
C39: 2150 | D39: Evangelism/Outreach Ministry/Web ministry | F39: =2500/12 -> 208.33333 | G39: =F39-E39 -> 208.33333
C40: 2170 | D40: Worship Service Ministry | F40: =2000/12 -> 166.66667 | G40: =F40-E40 -> 166.66667
C41: 2110 | D41: Church Events - CETR | F41: =1200/12 -> 100 | G41: =F41-E41 -> 100
...

Sheet Dec 2021
B2: Non-Profit Organization Income & Expenses Report
B3: Income & Expense February 2021
E4: Actual | F4: Budget | G4: Difference
B5: Income | E5: =SUM(E7:E8) -> 0 | F5: =SUM(F7:F8) -> 0 | G5: =E5-F5 -> 0
B6: Savings Account | E6: =E8 -> 0 | F6: =SUM(F7:F8) -> 0 | G6: =E6-F6 -> 0
C7: Building Fund Contribution | E7: 0 | F7: 0 | G7: =E7-F7 -> 0
C8: Bank Interest | F8: 0 | G8: =E8-F8 -> 0
B9: Checking Account | E9: =SUM(E10:E21) -> 0 | F9: =SUM(F10:F21) -> 7705.6533 | G9: =E9-F9 -> -7705.6533
C10: Benevolence Giving In | F10: 0 | G10: =E10-F10 -> 0
C11: MWBC Cooperative Giving | F11: 0 | G11: =E11-F11 -> 0
C12: Lakeland Cooperative Giving | F12: 0 | G12: =E12-F12 -> 0
C13: HBNA Cooperative Giving | F13: 0 | G13: =E13-F13 -> 0
C14: Plate Offering | F14: =92467.84/12 -> 7705.6533 | G14: =E14-F14 -> -7705.6533
C15: E-Tithing | F15: 0 | G15: =E15-F15 -> 0
C16: Fundraise | F16: 0 | G16: =E16-F16 -> 0
C17: Annie Armstrong/Lottie Moon | F17: 0 | G17: =E17-F17 -> 0
C18: Church Rental | F18: 0 | G18: =E18-F18 -> 0
C19: Children's Ministry | F19: 0 | G19: =E19-F19 -> 0
C20: Youth Funds (Donated by church members) | F20: 0 | G20: =E20-F20 -> 0
C21: Others (interest) | F21: 0 | G21: =E21-F21 -> 0
B22: Expenses | E22: =SUM(E23:E49) -> 0 | F22: =SUM(F23:F49) -> 7913.9867 | G22: =F22-E22 -> 7913.9867
C23: 3000 | D23: Church Mortgage | F23: =9447.84/12 -> 787.32 | G23: =F23-E23 -> 787.32
C24: 2350 | D24: Insurance, Tax & Fees | F24: =5020/12 -> 418.33333 | G24: =F24-E24 -> 418.33333
C25: 2320 | D25: Building Property & Ground Maint Upkeep | F25: =14300/12 -> 1191.6667 | G25: =F25-E25 -> 1191.6667
C26: 2330 | D26: Church Equipment Upgrade/Maint/Repair | F26: =3600/12 -> 300 | G26: =F26-E26 -> 300
C27: 2340 | D27: Utilities (Spect/Gas/Electric/Water/Sewage) | F27: =13100/12 -> 1091.6667 | G27: =F27-E27 -> 1091.6667
C28: 2310 | D28: Office Administration | F28: =1000/12 -> 83.333333 | G28: =F28-E28 -> 83.333333
C29: 1100 | D29: Cooperative Programs | F29: =1000/12 -> 83.333333 | G29: =F29-E29 -> 83.333333
B30: 1113+1122+1123 | D30: Annie Armstrong, Love&Care & Lottie Moon | F30: 0 | G30: =F30-E30 -> 0
C31: 2180 | D31: Guest Speaker Honor | G31: =F31-E31 -> 0
C32: 2100 | D32: Church Ministries | G32: =F32-E32 -> 0
C33: 2120 | D33: Sunday School Ministry/Nursery | F33: =2300/12 -> 191.66667 | G33: =F33-E33 -> 191.66667
C34: 2135 | D34: Deacons Ministry | F34: =1000/12 -> 83.333333 | G34: =F34-E34 -> 83.333333
C35: 2131 | D35: Womens Ministry | F35: =2000/12 -> 166.66667 | G35: =F35-E35 -> 166.66667
C36: 2132 | D36: Mens Ministry | F36: =500/12 -> 41.666667 | G36: =F36-E36 -> 41.666667
C37: 2133 | D37: Youth Ministry | F37: =500/12 -> 41.666667 | G37: =F37-E37 -> 41.666667
C38: 2040 | D38: General Training | F38: =2000/12 -> 166.66667
C39: 2150 | D39: Evangelism/Outreach Ministry/Web ministry | F39: =2500/12 -> 208.33333 | G39: =F39-E39 -> 208.33333
C40: 2170 | D40: Worship Service Ministry | F40: =2000/12 -> 166.66667 | G40: =F40-E40 -> 166.66667
C41: 2110 | D41: Church Events - CETR | F41: =1200/12 -> 100 | G41: =F41-E41 -> 100
...

Sheet Year End Report
B2: Non-Profit Organization Income & Expenses Report
B3: Income & Expense 2021
E4: Actual | F4: Budget | G4: Difference
B5: Income | E5: =SUM(E7:E8) -> 12.46 | F5: =SUM(F7:F8) -> 0 | G5: =E5-F5 -> 12.46
B6: Savings Account | E6: =E8 -> 12.46 | F6: =SUM(F7:F8) -> 0 | G6: =E6-F6 -> 12.46
C7: Building Fund Contribution | E7: 0 | F7: 0 | G7: =E7-F7 -> 0
C8: Bank Interest | E8: ='Jan 2021'!E8+'Feb 2021'!E8+'March 2021'!E8+'March 2021'!E8 -> 12.46 | F8: 0 | G8: =E8-F8 -> 12.46
B9: Checking Account | E9: =SUM(E10:E21) -> 7759.08 | F9: =SUM(F10:F21) -> 92467.84 | G9: =E9-F9 -> -84708.76
C10: Benevolence Giving In | F10: 0 | G10: =E10-F10 -> 0
C11: MWBC Cooperative Giving | F11: 0 | G11: =E11-F11 -> 0
C12: Lakeland Cooperative Giving | F12: 0 | G12: =E12-F12 -> 0
C13: HBNA Cooperative Giving | F13: 0 | G13: =E13-F13 -> 0
C14: Plate Offering | E14: ='Jan 2021'!E14+'Feb 2021'!E14 -> 3866 | F14: =92467.84 -> 92467.84 | G14: =E14-F14 -> -88601.84
C15: E-Tithing | E15: ='Jan 2021'!E15+'Feb 2021'!E15 -> 3888.91 | F15: 0 | G15: =E15-F15 -> 3888.91
C16: Fundraise | F16: 0 | G16: =E16-F16 -> 0
C17: Annie Armstrong/Lottie Moon | F17: 0 | G17: =E17-F17 -> 0
C18: Church Rental | F18: 0 | G18: =E18-F18 -> 0
C19: Children's Ministry | F19: 0 | G19: =E19-F19 -> 0
C20: Youth Funds (Donated by church members) | F20: 0 | G20: =E20-F20 -> 0
C21: Others (interest) | E21: ='Jan 2021'!E21+'Feb 2021'!E21 -> 4.17 | F21: 0 | G21: =E21-F21 -> 4.17
B22: Expenses | E22: =SUM(E23:E49) -> 12309.5 | F22: =SUM(F23:F49) -> 92467.84 | G22: =F22-E22 -> 80158.34
C23: 3000 | D23: Church Mortgage | E23: ='Jan 2021'!E23+'Feb 2021'!E23 -> 1574.64 | F23: =9447.84 -> 9447.84 | G23: =F23-E23 -> 7873.2
C24: 2350 | D24: Insurance, Tax & Fees | E24: ='Jan 2021'!E24+'Feb 2021'!E24 -> 472.12 | F24: =5020 -> 5020 | G24: =F24-E24 -> 4547.88
C25: 2320 | D25: Building Property & Ground Maint Upkeep | E25: ='Jan 2021'!E25+'Feb 2021'!E25 -> 1290.7 | F25: =14300 -> 14300 | G25: =F25-E25 -> 13009.3
C26: 2330 | D26: Church Equipment Upgrade/Maint/Repair | E26: ='Jan 2021'!E26+'Feb 2021'!E26 -> 290.7 | F26: =3600 -> 3600 | G26: =F26-E26 -> 3309.3
C27: 2340 | D27: Utilities (Spect/Gas/Electric/Water/Sewage) | E27: ='Jan 2021'!E27+'Feb 2021'!E27 -> 1923.59 | F27: =13100 -> 13100 | G27: =F27-E27 -> 11176.41
C28: 2310 | D28: Office Administration | E28: ='Jan 2021'!E28+'Feb 2021'!E28 -> 7.75 | F28: =1000 -> 1000 | G28: =F28-E28 -> 992.25
C29: 1100 | D29: Cooperative Programs | E29: ='Jan 2021'!E29+'Feb 2021'!E29 -> 0 | F29: =1000 -> 1000 | G29: =F29-E29 -> 1000
B30: 1113+1122+1123 | D30: Annie Armstrong, Love&Care & Lottie Moon | E30: ='Jan 2021'!E30+'Feb 2021'!E30 -> 0 | F30: 0 | G30: =F30-E30 -> 0
C31: 2180 | D31: Guest Speaker Honor | E31: ='Jan 2021'!E31+'Feb 2021'!F31 -> 0 | F31: 0 | G31: =F31-E31 -> 0
C32: 2100 | D32: Church Ministries | G32: =F32-E32 -> 0
C33: 2120 | D33: Sunday School Ministry/Nursery | E33: ='Jan 2021'!E33+'Feb 2021'!E33 -> 0 | F33: =2300 -> 2300 | G33: =F33-E33 -> 2300
C34: 2135 | D34: Deacons Ministry | E34: ='Jan 2021'!E34+'Feb 2021'!E34 -> 0 | F34: =1000 -> 1000 | G34: =F34-E34 -> 1000
C35: 2131 | D35: Womens Ministry | E35: ='Jan 2021'!E35+'Feb 2021'!E35 -> 0 | F35: =2000 -> 2000 | G35: =F35-E35 -> 2000
C36: 2132 | D36: Mens Ministry | E36: ='Jan 2021'!E36+'Feb 2021'!E36 -> 0 | F36: =500 -> 500 | G36: =F36-E36 -> 500
C37: 2133 | D37: Youth Ministry | E37: ='Jan 2021'!E37+'Feb 2021'!E37 -> 0 | F37: =500 -> 500 | G37: =F37-E37 -> 500
C38: 2040 | D38: General Training | E38: ='Jan 2021'!E38+'Feb 2021'!E38 -> 0 | F38: =2000 -> 2000
C39: 2150 | D39: Evangelism/Outreach Ministry/Web Ministry | E39: ='Jan 2021'!E39+'Feb 2021'!E39 -> 0 | F39: 0 | G39: =F39-E39 -> 0
C40: 2170 | D40: Worship Service Ministry | E40: ='Jan 2021'!E40+'Feb 2021'!E40 -> 0 | F40: =2000 -> 2000 | G40: =F40-E40 -> 2000
C41: 2110 | D41: Church Events - CETR | E41: ='Jan 2021'!E41+'Feb 2021'!E41 -> 0 | F41: =1200 -> 1200 | G41: =F41-E41 -> 1200
...
